2016-02-18 09:58:30,117 (26437/MainThread) pgcli.main ERROR - traceback: 'Traceback (most recent call last):\n  File "/usr/local/Cellar/pgcli/0.20.1/libexec/lib/python2.7/site-packages/pgcli/main.py", line 235, in connect\n    raise e\nOperationalError: FATAL:  database "app_db" does not exist\n\n'
2016-02-18 10:33:22,382 (27581/MainThread) pgcli.main ERROR - sql: u'\\e ACCESS', error: RuntimeError(u'Error reading file: ACCESS.',)
2016-02-18 10:33:22,387 (27581/MainThread) pgcli.main ERROR - traceback: 'Traceback (most recent call last):\n  File "/usr/local/Cellar/pgcli/0.20.1/libexec/lib/python2.7/site-packages/pgcli/main.py", line 295, in run_cli\n    document = self.handle_editor_command(self.cli, document)\n  File "/usr/local/Cellar/pgcli/0.20.1/libexec/lib/python2.7/site-packages/pgcli/main.py", line 264, in handle_editor_command\n    raise RuntimeError(message)\nRuntimeError: Error reading file: ACCESS.\n'
